Workbook

Sheet PLOs
H1: المجال الأول : عمق المعرفة / Knowledge and Understanding | Q1: المجال الثاني : المهارات / Skills /Critical أولاً : التفكير الناقد /Critical Thinking | W1: المجال الثاني : المهارات / Skills /Critical ثانياً : التواصل الفعال /Effective communication | AA1: المجال الثاني : المهارات / Skills /Critical Thinking ثالثاً : المهارات التقنية /Technical skills | AG1: المجال الثاني : المهارات / Skills /Critical Thinking رابعاً :الابتكار وريادة الأعمال/Innovation and Entrepreneurship | AI1: المجال الثاني : المهارات / Skills /Critical Thinking خامساً : البحث العلمي /Research | AK1: المجال الثالث : القيم / Values أولاً : القيادة والمسؤولية /Leadership and Responsibility | AM1: المجال الثالث : القيم / Values ثانياً :المبادرة و التكيف /Initiative and adaptation | AO1: المجال الثالث : القيم / Values ثالثاً :النزاهة و أخلاقيات المهنة/Integrity and Professional ethics | AQ1: المجال الثالث : القيم / Values رابعاً : الوسطية و الاعتزاز بالهوية الوطنية/ | AS1: المجال الثالث : القيم / Values خامساً: التعلم مدى الحياة / Lifelong learning | AU1: المجال الثالث : القيم / Values سادساً :العمل التطوعي و المسؤولية المجتمعية /Volunteer work and social responsibility
A2: اسم البرنامج Program Name | B2: المخرج التعليمي لعمق المعرفة / Knowledge & Understanding output (K1) | C2: قيمة المخرج التعليمي لعمق المعرفة / ( K1 ) Output value | D2: المخرج التعليمي لعمق المعرفة /Knowledge & Understanding output (K2) | E2: قيمة المخرج التعليمي لعمق المعرفة / Output value ( K2 ) | F2: المخرج التعليمي لعمق المعرفة /Knowledge & Understanding output (K3) | G2: قيمة المخرج التعليمي لعمق المعرفة / Output value ( K3 ) | H2: المخرج التعليمي لعمق المعرفة /Knowledge & Understanding output (K4) | I2: قيمة المخرج التعليمي لعمق المعرفة / Output value ( K4 ) | J2: المخرج التعليمي لعمق المعرفة /Knowledge & Understanding output (K5) | K2: قيمة المخرج التعليمي لعمق المعرفة / Output value ( K5 ) | L2: المخرج التعليمي للتفكير الناقد / Critical Thinking output (S1) | M2: قيمة المخرج التعليمي للتفكير الناقد /Output value (S1) | N2: المخرج التعليمي للتفكير الناقد /Critical Thinking output (S2) | O2: قيمة المخرج التعليمي للتفكير الناقد / Output value (S2) | P2: المخرج التعليمي للتفكير الناقد للتفكير الناقد /Critical Thinking output (S3) | Q2: قيمة المخرج التعليمي للتفكير الناقد / Output value (S3) | R2: المخرج التعليمي للتواصل الفعال / Effective communication output (S1) | S2: قيمة المخرج التعليمي للتواصل الفعال / Output value (S1) | T2: المخرج التعليمي للتواصل الفعال/ Effective communication output (S2) | U2: قيمة المخرج التعليمي للتواصل الفعال/Output value (S2) | V2: المخرج التعليمي للمهارات التقنية / Technical skills output (S1) | W2: قيمة المخرج التعليمي للمهارات التقنية / Output value (S1) | X2: المخرج التعليمي للمهارات التقنية / Technical skills output (S2) | Y2: قيمة المخرج التعليمي للمهارات التقنية / Output value (S2) | Z2: المخرج التعليمي للمهارات التقنية / Technical skills output (S3) | AA2: قيمة المخرج التعليمي للمهارات التقنية / Output value (S3) | AB2: المخرج التعليمي للإبتكار و ريادة الأعمال /Innovation and Entrepreneurship output (S1) | AC2: قيمة المخرج التعليمي للإبتكار و ريادة الأعمال / Output value (S1) | AD2: المخرج التعليمي للبحث العلمي / Research output (S1) | AE2: قيمة المخرج التعليمي للبحث العلمي / Output value (S1) | AF2: المخرج التعليمي للقيادة والمسؤولية / Leadership and Responsibility output (V1) | AG2: قيمة المخرج التعليمي للقيادة والمسؤولية / Output value ( V1) | AH2: المخرج التعليمي للمبادرة والتكيف / Initiative and adaptation output (V1) | AI2: قيمة المخرج التعليمي المبادرة و التكيف/ Output value ( v1 ) | AJ2: المخرج التعليمي للنزاهةو أخلاقيات المهنة / Integrity and Professional ethics output (V1) | AK2: قيمة المخرج التعليمي النزاهة وأخلاقيات المهنة/ Output value (V1 ) | AL2: المخرج التعليمي للوسطية و الاعتزاز بالهوية الوطنية / Moderation and Pride in national identity output (V1) | AM2: قيمة المخرج التعليمي الوسطية و الاعتزاز بالهوية الوطنية / Output value (V1) | AN2: المخرج التعليمي للتعلم مدى الحياة / Lifelong learning output (V1) | AO2: قيمة المخرج التعليمي للتعلم مدى الحياة / Output value (V1) | AP2: المخرج التعليمي للعمل التطوعي والمسؤولية المجتمعية / Volunteer work and social responsibility output (V1) | AQ2: قيمة المخرج التعليمي للعمل التطوعي والمسؤولية المجتمعية / Output value ( V1 )
A3: برنامج التصميم الجرافيكي (بكالوريوس) - كلية الفنون | B3: (ع1) يتعرف على المفاهيم والنظريات والاتجاهات الفنية في مجال التصميم الجرافيكي. | C3: 0.75 | D3: (ع2) يستعرض خصائص الخامات الرقمية والأدوات والتطبيقات التقنية وطرق استخدامها. | E3: 0.75 | F3: (ع3) يوضح الأساليب الفنية والتقنية والبحثية المختلفة في مجال التصميم الجرافيكي. | G3: 0.75 | L3: (م1) يقارن بين الأدوات والأساليب التقنية والمعرفية في مجال التصميم الجرافيكي. | M3: 0.75 | N3: (م2) يطبق المفاهيم والمهارات والاستراتيجيات والنظريات في مجال التصميم الجرافيكي. | O3: 0.75 | R3: (ق3) يتعاون بفاعلية ضمن مجموعات العمل من خلال العروض التقديمية والكتابية لبناء العلاقات المهنية. | S3: 0.75 | T3: (م4) ينتج أعمال وتقارير ومشاريع مبتكرة في مجال التصميم الجرافيكي تساهم في الرفع من جودة الحياة. | U3: 0.75 | V3: (م3) يصمم باستخدام التقنيات والبرامج لإنتاج أعمال تساهم في تعزيز الهوية الوطنية والثقافية. | W3: 0.75 | X3: (م2) يطبق المفاهيم والمهارات والاستراتيجيات والنظريات في مجال التصميم الجرافيكي. | Y3: 0.75 | Z3: (م1) يقارن بين الأدوات والأساليب التقنية والمعرفية في مجال التصميم الجرافيكي. | AA3: 0.75 | AB3: (م4) ينتج أعمال وتقارير ومشاريع مبتكرة في مجال التصميم الجرافيكي تساهم في الرفع من جودة الحياة. | AC3: 0.75 | AD3: (م4) ينتج أعمال وتقارير ومشاريع مبتكرة في مجال التصميم الجرافيكي تساهم في الرفع من جودة الحياة. | AE3: 0.75 | AF3: (ق3) يتعاون بفاعلية ضمن مجموعات العمل من خلال العروض التقديمية والكتابية لبناء العلاقات المهنية. | AG3: 0.75 | AJ3: (ق1) يلتزم بالأخلاقيات المهنية والحقوق الفكرية في التصميم. | AK3: 0.75 | AL3: (ق2) يقدر أهمية العمل اليدوي والتقني وارتباطه بالهوية الثقافية. | AM3: 0.75 | AP3: (م4) ينتج أعمال وتقارير ومشاريع مبتكرة في مجال التصميم الجرافيكي تساهم في الرفع من جودة الحياة. | AQ3: 0.75

Sheet Results
A1: درجة البرنامج Program Degree | B1: الكليات الصحية Health Colleges | C1: الكليات العلمية Science Colleges | D1: الكليات الانسانية Humanities Colleges | E1: كلية الدراسات التطبيقية College of Applied Studies | F1: المخرج التعليمي لعمق المعرفة / Knowledge & Understanding output (K1) | G1: قيمة المخرج التعليمي / ( K1 ) Output value | H1: المخرج التعليمي لعمق المعرفة /Knowledge & Understanding output (K2) | I1: قيمة المخرج التعليمي / Output value ( K2 ) | J1: المخرج التعليمي لعمق المعرفة /Knowledge & Understanding output (K3) | K1: قيمة المخرج التعليمي / Output value ( K3 ) | L1: المخرج التعليمي لعمق المعرفة /Knowledge & Understanding output (K4) | M1: قيمة المخرج التعليمي / Output value ( K4 ) | N1: المخرج التعليمي للتفكير الناقد / Critical Thinking output (S1) | O1: قيمة المخرج التعليمي /Output value (S1) | P1: المخرج التعليمي للتفكير الناقد /Critical Thinking output (S2) | Q1: قيمة المخرج التعليمي / Output value (S2) | R1: المخرج التعليمي للتفكير الناقد /Critical Thinking output (S3) | S1: قيمة المخرج التعليمي / Output value (S3) | T1: المخرج التعليمي للتواصل الفعال / Effective communication output (S1) | U1: قيمة المخرج التعليمي / Output value (S1) | V1: المخرج التعليمي للتواصل الفعال/ Effective communication output (S2) | W1: قيمة المخرج التعليمي/Output value (S2) | X1: المخرج التعليمي للمهارات التقنية / Technical skills output (S1) | Y1: قيمة المخرج التعليمي / Output value (S1) | Z1: المخرج التعليمي للإبتكار و ريادة الأعمال /Innovation and Entrepreneurship output (S1) | AA1: قيمة المخرج التعليمي / Output value (S1) | AB1: المخرج التعليمي للبحث العلمي / Research output (S1) | AC1: قيمة المخرج التعليمي / Output value (S1) | AD1: المخرج التعليمي للقيادة والمسؤولية / Leadership and Responsibility output (V1) | AE1: قيمة المخرج التعليمي / Output value ( V1) | AF1: المخرج التعليمي للمبادرة والتكيف / Initiative and adaptation output (V1) | AG1: قيمة المخرج التعليمي / Output value ( v1 ) | AH1: المخرج التعليمي للنزاهةو أخلاقيات المهنة / Integrity and Professional ethics output (V1) | AI1: قيمة المخرج التعليمي/ Output value (V1 ) | AJ1: المخرج التعليمي للوسطية و الاعتزاز بالهوية الوطنية / Moderation and Pride in national identity output (V1) | AK1: قيمة المخرج التعليمي / Output value (V1) | AL1: المخرج التعليمي للتعلم مدى الحياة / Lifelong learning output (V1) | AM1: قيمة المخرج التعليمي للتعلم مدى الحياة / Output value (V1) | AN1: المخرج التعليمي للعمل التطوعي والمسؤولية المجتمعية / Volunteer work and social responsibility output (V1) | AO1: قيمة المخرج التعليمي / Output value ( V1 )
A2: بكالوريوس Bachelor's | B2: كلية الطب College of Medicine | C2: كلية الهندسة College of Engineering | D2: كلية الحقوق والعلوم السياسية College of Law and Political Sciences | F2: =ISTEXT(PLOs!#REF!) | G2: =ISNUMBER(PLOs!#REF!) | H2: =ISTEXT(PLOs!#REF!) | I2: =ISNUMBER(PLOs!#REF!) | J2: =ISTEXT(PLOs!#REF!) | K2: =ISNUMBER(PLOs!#REF!) | L2: =ISTEXT(PLOs!#REF!) | M2: =ISNUMBER(PLOs!#REF!) | N2: =ISTEXT(PLOs!#REF!) | O2: =ISNUMBER(PLOs!#REF!) | P2: =ISTEXT(PLOs!#REF!) | Q2: =ISNUMBER(PLOs!#REF!) | R2: =ISTEXT(PLOs!#REF!) | S2: =ISNUMBER(PLOs!#REF!) | T2: =ISTEXT(PLOs!#REF!) | U2: =ISNUMBER(PLOs!#REF!) | V2: =ISTEXT(PLOs!#REF!) | W2: =ISNUMBER(PLOs!#REF!) | X2: =ISTEXT(PLOs!#REF!) | Y2: =ISNUMBER(PLOs!#REF!) | Z2: =ISTEXT(PLOs!#REF!) | AA2: =ISNUMBER(PLOs!#REF!) | AB2: =ISTEXT(PLOs!#REF!) | AC2: =ISNUMBER(PLOs!#REF!) | AD2: =ISTEXT(PLOs!#REF!) | AE2: =ISNUMBER(PLOs!#REF!) | AF2: =ISTEXT(PLOs!#REF!) | AG2: =ISNUMBER(PLOs!#REF!) | AH2: =ISTEXT(PLOs!#REF!) | AI2: =ISNUMBER(PLOs!#REF!) | AJ2: =ISTEXT(PLOs!#REF!) | AK2: =ISNUMBER(PLOs!#REF!) | AL2: =ISTEXT(PLOs!#REF!) | AM2: =ISNUMBER(PLOs!#REF!) | AN2: =ISTEXT(PLOs!#REF!) | AO2: =ISNUMBER(PLOs!#REF!)
A3: دراسات عليا ( ماجستير ) Masters | B3: كلية الصيدلة College of Pharmacy | C3: كلية العلوم College of Science | D3: كلية اللغات والترجمة College of Languages and Translation | F3: =ISTEXT(PLOs!B3) | G3: =ISNUMBER(PLOs!C3) | H3: =ISTEXT(PLOs!D3) | I3: =ISNUMBER(PLOs!E3) | J3: =ISTEXT(PLOs!F3) | K3: =ISNUMBER(PLOs!G3) | L3: =ISTEXT(PLOs!H3) | M3: =ISNUMBER(PLOs!I3) | N3: =ISTEXT(PLOs!L3) | O3: =ISNUMBER(PLOs!M3) | P3: =ISTEXT(PLOs!N3) | Q3: =ISNUMBER(PLOs!O3) | R3: =ISTEXT(PLOs!P3) | S3: =ISNUMBER(PLOs!Q3) | T3: =ISTEXT(PLOs!R3) | U3: =ISNUMBER(PLOs!S3) | V3: =ISTEXT(PLOs!T3) | W3: =ISNUMBER(PLOs!U3) | X3: =ISTEXT(PLOs!V3) | Y3: =ISNUMBER(PLOs!W3) | Z3: =ISTEXT(PLOs!AB3) | AA3: =ISNUMBER(PLOs!AC3) | AB3: =ISTEXT(PLOs!AD3) | AC3: =ISNUMBER(PLOs!AE3) | AD3: =ISTEXT(PLOs!AF3) | AE3: =ISNUMBER(PLOs!AG3) | AF3: =ISTEXT(PLOs!AH3) | AG3: =ISNUMBER(PLOs!AI3) | AH3: =ISTEXT(PLOs!AJ3) | AI3: =ISNUMBER(PLOs!AK3) | AJ3: =ISTEXT(PLOs!AL3) | AK3: =ISNUMBER(PLOs!AM3) | AL3: =ISTEXT(PLOs!AN3) | AM3: =ISNUMBER(PLOs!AO3) | AN3: =ISTEXT(PLOs!AP3) | AO3: =ISNUMBER(PLOs!AQ3)
A4: دراسات عليا ( دكتوراه ) PhD | B4: كلية طب الأسنان College of Dentistry | C4: كلية علوم الأغذية والزراعة College of Food and Agricultural Sciences | D4: كلية العلوم الإنسانية والإجتماعية College of Humanities and Social Sciences | F4: =ISTEXT(PLOs!B4) | G4: =ISNUMBER(PLOs!C4) | H4: =ISTEXT(PLOs!D4) | I4: =ISNUMBER(PLOs!E4) | J4: =ISTEXT(PLOs!F4) | K4: =ISNUMBER(PLOs!G4) | L4: =ISTEXT(PLOs!H4) | M4: =ISNUMBER(PLOs!I4) | N4: =ISTEXT(PLOs!L4) | O4: =ISNUMBER(PLOs!M4) | P4: =ISTEXT(PLOs!N4) | Q4: =ISNUMBER(PLOs!O4) | R4: =ISTEXT(PLOs!P4) | S4: =ISNUMBER(PLOs!Q4) | T4: =ISTEXT(PLOs!R4) | U4: =ISNUMBER(PLOs!S4) | V4: =ISTEXT(PLOs!T4) | W4: =ISNUMBER(PLOs!U4) | X4: =ISTEXT(PLOs!V4) | Y4: =ISNUMBER(PLOs!W4) | Z4: =ISTEXT(PLOs!AB4) | AA4: =ISNUMBER(PLOs!AC4) | AB4: =ISTEXT(PLOs!AD4) | AC4: =ISNUMBER(PLOs!AE4) | AD4: =ISTEXT(PLOs!AF4) | AE4: =ISNUMBER(PLOs!AG4) | AF4: =ISTEXT(PLOs!AH4) | AG4: =ISNUMBER(PLOs!AI4) | AH4: =ISTEXT(PLOs!AJ4) | AI4: =ISNUMBER(PLOs!AK4) | AJ4: =ISTEXT(PLOs!AL4) | AK4: =ISNUMBER(PLOs!AM4) | AL4: =ISTEXT(PLOs!AN4) | AM4: =ISNUMBER(PLOs!AO4) | AN4: =ISTEXT(PLOs!AP4) | AO4: =ISNUMBER(PLOs!AQ4)
A5: دبلوم Diploma | B5: كلية العلوم الطبية التطبيقية College of Applied Medical Sciences | C5: كلية علوم الحاسب والمعلومات College of Computer and Information Sciences | D5: كلية علوم الرياضة والنشاط البدني College of Sport Sciences and Physical Activity | F5: =ISTEXT(PLOs!B8) | G5: =ISNUMBER(PLOs!C8) | H5: =ISTEXT(PLOs!D8) | I5: =ISNUMBER(PLOs!E8) | J5: =ISTEXT(PLOs!F8) | K5: =ISNUMBER(PLOs!G8) | L5: =ISTEXT(PLOs!H8) | M5: =ISNUMBER(PLOs!I8) | N5: =ISTEXT(PLOs!L8) | O5: =ISNUMBER(PLOs!M8) | P5: =ISTEXT(PLOs!N8) | Q5: =ISNUMBER(PLOs!O8) | R5: =ISTEXT(PLOs!P8) | S5: =ISNUMBER(PLOs!Q8) | T5: =ISTEXT(PLOs!R8) | U5: =ISNUMBER(PLOs!S8) | V5: =ISTEXT(PLOs!T8) | W5: =ISNUMBER(PLOs!U8) | X5: =ISTEXT(PLOs!V8) | Y5: =ISNUMBER(PLOs!W8) | Z5: =ISTEXT(PLOs!AB8) | AA5: =ISNUMBER(PLOs!AC8) | AB5: =ISTEXT(PLOs!AD8) | AC5: =ISNUMBER(PLOs!AE8) | AD5: =ISTEXT(PLOs!AF8) | AE5: =ISNUMBER(PLOs!AG8) | AF5: =ISTEXT(PLOs!AH8) | AG5: =ISNUMBER(PLOs!AI8) | AH5: =ISTEXT(PLOs!AJ8) | AI5: =ISNUMBER(PLOs!AK8) | AJ5: =ISTEXT(PLOs!AL8) | AK5: =ISNUMBER(PLOs!AM8) | AL5: =ISTEXT(PLOs!AN8) | AM5: =ISNUMBER(PLOs!AO8) | AN5: =ISTEXT(PLOs!AP8) | AO5: =ISNUMBER(PLOs!AQ8)
B6: كلية التمريض College of Nursing | C6: كلية العمارة والتخطيط College of Architecture and Planning | D6: كلية التربية College of Education | F6: =ISTEXT(PLOs!B9) | G6: =ISNUMBER(PLOs!C9) | H6: =ISTEXT(PLOs!D9) | I6: =ISNUMBER(PLOs!E9) | J6: =ISTEXT(PLOs!F9) | K6: =ISNUMBER(PLOs!G9) | L6: =ISTEXT(PLOs!H9) | M6: =ISNUMBER(PLOs!I9) | N6: =ISTEXT(PLOs!L9) | O6: =ISNUMBER(PLOs!M9) | P6: =ISTEXT(PLOs!N9) | Q6: =ISNUMBER(PLOs!O9) | R6: =ISTEXT(PLOs!P9) | S6: =ISNUMBER(PLOs!Q9) | T6: =ISTEXT(PLOs!R9) | U6: =ISNUMBER(PLOs!S9) | V6: =ISTEXT(PLOs!T9) | W6: =ISNUMBER(PLOs!U9) | X6: =ISTEXT(PLOs!V9) | Y6: =ISNUMBER(PLOs!W9) | Z6: =ISTEXT(PLOs!AB9) | AA6: =ISNUMBER(PLOs!AC9) | AB6: =ISTEXT(PLOs!AD9) | AC6: =ISNUMBER(PLOs!AE9) | AD6: =ISTEXT(PLOs!AF9) | AE6: =ISNUMBER(PLOs!AG9) | AF6: =ISTEXT(PLOs!AH9) | AG6: =ISNUMBER(PLOs!AI9) | AH6: =ISTEXT(PLOs!AJ9) | AI6: =ISNUMBER(PLOs!AK9) | AJ6: =ISTEXT(PLOs!AL9) | AK6: =ISNUMBER(PLOs!AM9) | AL6: =ISTEXT(PLOs!AN9) | AM6: =ISNUMBER(PLOs!AO9) | AN6: =ISTEXT(PLOs!AP9) | AO6: =ISNUMBER(PLOs!AQ9)
B7: كلية الأمير سلطان بن عبدالعزيز للخدمات الطبية الطارئة Prince Sultan Bin Abdulaziz College for Emergency Medical Services | C7: كلية إدارة الأعمال College of Business Administration | D7: كلية السياحة والآثار College of Tourism and Archeology | F7: =ISTEXT(PLOs!#REF!) | G7: =ISNUMBER(PLOs!#REF!) | H7: =ISTEXT(PLOs!#REF!) | I7: =ISNUMBER(PLOs!#REF!) | J7: =ISTEXT(PLOs!#REF!) | K7: =ISNUMBER(PLOs!#REF!) | L7: =ISTEXT(PLOs!#REF!) | M7: =ISNUMBER(PLOs!#REF!) | N7: =ISTEXT(PLOs!#REF!) | O7: =ISNUMBER(PLOs!#REF!) | P7: =ISTEXT(PLOs!#REF!) | Q7: =ISNUMBER(PLOs!#REF!) | R7: =ISTEXT(PLOs!#REF!) | S7: =ISNUMBER(PLOs!#REF!) | T7: =ISTEXT(PLOs!#REF!) | U7: =ISNUMBER(PLOs!#REF!) | V7: =ISTEXT(PLOs!#REF!) | W7: =ISNUMBER(PLOs!#REF!) | X7: =ISTEXT(PLOs!#REF!) | Y7: =ISNUMBER(PLOs!#REF!) | Z7: =ISTEXT(PLOs!#REF!) | AA7: =ISNUMBER(PLOs!#REF!) | AB7: =ISTEXT(PLOs!#REF!) | AC7: =ISNUMBER(PLOs!#REF!) | AD7: =ISTEXT(PLOs!#REF!) | AE7: =ISNUMBER(PLOs!#REF!) | AF7: =ISTEXT(PLOs!#REF!) | AG7: =ISNUMBER(PLOs!#REF!) | AH7: =ISTEXT(PLOs!#REF!) | AI7: =ISNUMBER(PLOs!#REF!) | AJ7: =ISTEXT(PLOs!#REF!) | AK7: =ISNUMBER(PLOs!#REF!) | AL7: =ISTEXT(PLOs!#REF!) | AM7: =ISNUMBER(PLOs!#REF!) | AN7: =ISTEXT(PLOs!#REF!) | AO7: =ISNUMBER(PLOs!#REF!)
C8: كليات المزاحمية Colleges of Muzahimya Branch | D8: كلية الفنون College of Art | F8: =ISTEXT(PLOs!#REF!) | G8: =ISNUMBER(PLOs!#REF!) | H8: =ISTEXT(PLOs!#REF!) | I8: =ISNUMBER(PLOs!#REF!) | J8: =ISTEXT(PLOs!#REF!) | K8: =ISNUMBER(PLOs!#REF!) | L8: =ISTEXT(PLOs!#REF!) | M8: =ISNUMBER(PLOs!#REF!) | N8: =ISTEXT(PLOs!#REF!) | O8: =ISNUMBER(PLOs!#REF!) | P8: =ISTEXT(PLOs!#REF!) | Q8: =ISNUMBER(PLOs!#REF!) | R8: =ISTEXT(PLOs!#REF!) | S8: =ISNUMBER(PLOs!#REF!) | T8: =ISTEXT(PLOs!#REF!) | U8: =ISNUMBER(PLOs!#REF!) | V8: =ISTEXT(PLOs!#REF!) | W8: =ISNUMBER(PLOs!#REF!) | X8: =ISTEXT(PLOs!#REF!) | Y8: =ISNUMBER(PLOs!#REF!) | Z8: =ISTEXT(PLOs!#REF!) | AA8: =ISNUMBER(PLOs!#REF!) | AB8: =ISTEXT(PLOs!#REF!) | AC8: =ISNUMBER(PLOs!#REF!) | AD8: =ISTEXT(PLOs!#REF!) | AE8: =ISNUMBER(PLOs!#REF!) | AF8: =ISTEXT(PLOs!#REF!) | AG8: =ISNUMBER(PLOs!#REF!) | AH8: =ISTEXT(PLOs!#REF!) | AI8: =ISNUMBER(PLOs!#REF!) | AJ8: =ISTEXT(PLOs!#REF!) | AK8: =ISNUMBER(PLOs!#REF!) | AL8: =ISTEXT(PLOs!#REF!) | AM8: =ISNUMBER(PLOs!#REF!) | AN8: =ISTEXT(PLOs!#REF!) | AO8: =ISNUMBER(PLOs!#REF!)
F9: =ISTEXT(PLOs!#REF!) | G9: =ISNUMBER(PLOs!#REF!) | H9: =ISTEXT(PLOs!#REF!) | I9: =ISNUMBER(PLOs!#REF!) | J9: =ISTEXT(PLOs!#REF!) | K9: =ISNUMBER(PLOs!#REF!) | L9: =ISTEXT(PLOs!#REF!) | M9: =ISNUMBER(PLOs!#REF!) | N9: =ISTEXT(PLOs!#REF!) | O9: =ISNUMBER(PLOs!#REF!) | P9: =ISTEXT(PLOs!#REF!) | Q9: =ISNUMBER(PLOs!#REF!) | R9: =ISTEXT(PLOs!#REF!) | S9: =ISNUMBER(PLOs!#REF!) | T9: =ISTEXT(PLOs!#REF!) | U9: =ISNUMBER(PLOs!#REF!) | V9: =ISTEXT(PLOs!#REF!) | W9: =ISNUMBER(PLOs!#REF!) | X9: =ISTEXT(PLOs!#REF!) | Y9: =ISNUMBER(PLOs!#REF!) | Z9: =ISTEXT(PLOs!#REF!) | AA9: =ISNUMBER(PLOs!#REF!) | AB9: =ISTEXT(PLOs!#REF!) | AC9: =ISNUMBER(PLOs!#REF!) | AD9: =ISTEXT(PLOs!#REF!) | AE9: =ISNUMBER(PLOs!#REF!) | AF9: =ISTEXT(PLOs!#REF!) | AG9: =ISNUMBER(PLOs!#REF!) | AH9: =ISTEXT(PLOs!#REF!) | AI9: =ISNUMBER(PLOs!#REF!) | AJ9: =ISTEXT(PLOs!#REF!) | AK9: =ISNUMBER(PLOs!#REF!) | AL9: =ISTEXT(PLOs!#REF!) | AM9: =ISNUMBER(PLOs!#REF!) | AN9: =ISTEXT(PLOs!#REF!) | AO9: =ISNUMBER(PLOs!#REF!)
F10: =ISTEXT(PLOs!B10) | G10: =ISNUMBER(PLOs!C10) | H10: =ISTEXT(PLOs!D10) | I10: =ISNUMBER(PLOs!E10) | J10: =ISTEXT(PLOs!F10) | K10: =ISNUMBER(PLOs!G10) | L10: =ISTEXT(PLOs!H10) | M10: =ISNUMBER(PLOs!I10) | N10: =ISTEXT(PLOs!L10) | O10: =ISNUMBER(PLOs!M10) | P10: =ISTEXT(PLOs!N10) | Q10: =ISNUMBER(PLOs!O10) | R10: =ISTEXT(PLOs!P10) | S10: =ISNUMBER(PLOs!Q10) | T10: =ISTEXT(PLOs!R10) | U10: =ISNUMBER(PLOs!S10) | V10: =ISTEXT(PLOs!T10) | W10: =ISNUMBER(PLOs!U10) | X10: =ISTEXT(PLOs!V10) | Y10: =ISNUMBER(PLOs!W10) | Z10: =ISTEXT(PLOs!AB10) | AA10: =ISNUMBER(PLOs!AC10) | AB10: =ISTEXT(PLOs!AD10) | AC10: =ISNUMBER(PLOs!AE10) | AD10: =ISTEXT(PLOs!AF10) | AE10: =ISNUMBER(PLOs!AG10) | AF10: =ISTEXT(PLOs!AH10) | AG10: =ISNUMBER(PLOs!AI10) | AH10: =ISTEXT(PLOs!AJ10) | AI10: =ISNUMBER(PLOs!AK10) | AJ10: =ISTEXT(PLOs!AL10) | AK10: =ISNUMBER(PLOs!AM10) | AL10: =ISTEXT(PLOs!AN10) | AM10: =ISNUMBER(PLOs!AO10) | AN10: =ISTEXT(PLOs!AP10) | AO10: =ISNUMBER(PLOs!AQ10)
F11: =ISTEXT(PLOs!E11) | G11: =ISNUMBER(PLOs!F11) | H11: =ISTEXT(PLOs!G11) | I11: =ISNUMBER(PLOs!H11) | J11: =ISTEXT(PLOs!I11) | K11: =ISNUMBER(PLOs!J11) | L11: =ISTEXT(PLOs!K11) | M11: =ISNUMBER(PLOs!L11) | N11: =ISTEXT(PLOs!O11) | O11: =ISNUMBER(PLOs!P11) | P11: =ISTEXT(PLOs!Q11) | Q11: =ISNUMBER(PLOs!R11) | R11: =ISTEXT(PLOs!S11) | S11: =ISNUMBER(PLOs!T11) | T11: =ISTEXT(PLOs!U11) | U11: =ISNUMBER(PLOs!V11) | V11: =ISTEXT(PLOs!W11) | W11: =ISNUMBER(PLOs!X11) | X11: =ISTEXT(PLOs!Y11) | Y11: =ISNUMBER(PLOs!Z11) | Z11: =ISTEXT(PLOs!AE11) | AA11: =ISNUMBER(PLOs!AF11) | AB11: =ISTEXT(PLOs!AG11) | AC11: =ISNUMBER(PLOs!AH11) | AD11: =ISTEXT(PLOs!AI11) | AE11: =ISNUMBER(PLOs!AJ11) | AF11: =ISTEXT(PLOs!AK11) | AG11: =ISNUMBER(PLOs!AL11) | AH11: =ISTEXT(PLOs!AM11) | AI11: =ISNUMBER(PLOs!AN11) | AJ11: =ISTEXT(PLOs!AO11) | AK11: =ISNUMBER(PLOs!AP11) | AL11: =ISTEXT(PLOs!AQ11) | AM11: =ISNUMBER(PLOs!AR11) | AN11: =ISTEXT(PLOs!AS11) | AO11: =ISNUMBER(PLOs!AT11)
F12: =ISTEXT(PLOs!F13) | G12: =ISNUMBER(PLOs!G13) | H12: =ISTEXT(PLOs!H13) | I12: =ISNUMBER(PLOs!I13) | J12: =ISTEXT(PLOs!J13) | K12: =ISNUMBER(PLOs!K13) | L12: =ISTEXT(PLOs!L13) | M12: =ISNUMBER(PLOs!M13) | N12: =ISTEXT(PLOs!P13) | O12: =ISNUMBER(PLOs!Q13) | P12: =ISTEXT(PLOs!R13) | Q12: =ISNUMBER(PLOs!S13) | R12: =ISTEXT(PLOs!T13) | S12: =ISNUMBER(PLOs!U13) | T12: =ISTEXT(PLOs!V13) | U12: =ISNUMBER(PLOs!W13) | V12: =ISTEXT(PLOs!X13) | W12: =ISNUMBER(PLOs!Y13) | X12: =ISTEXT(PLOs!Z13) | Y12: =ISNUMBER(PLOs!AA13) | Z12: =ISTEXT(PLOs!AF13) | AA12: =ISNUMBER(PLOs!AG13) | AB12: =ISTEXT(PLOs!AH13) | AC12: =ISNUMBER(PLOs!AI13) | AD12: =ISTEXT(PLOs!AJ13) | AE12: =ISNUMBER(PLOs!AK13) | AF12: =ISTEXT(PLOs!AL13) | AG12: =ISNUMBER(PLOs!AM13) | AH12: =ISTEXT(PLOs!AN13) | AI12: =ISNUMBER(PLOs!AO13) | AJ12: =ISTEXT(PLOs!AP13) | AK12: =ISNUMBER(PLOs!AQ13) | AL12: =ISTEXT(PLOs!AR13) | AM12: =ISNUMBER(PLOs!AS13) | AN12: =ISTEXT(PLOs!AT13) | AO12: =ISNUMBER(PLOs!AU13)
F13: =ISTEXT(PLOs!F14) | G13: =ISNUMBER(PLOs!G14) | H13: =ISTEXT(PLOs!H14) | I13: =ISNUMBER(PLOs!I14) | J13: =ISTEXT(PLOs!J14) | K13: =ISNUMBER(PLOs!K14) | L13: =ISTEXT(PLOs!L14) | M13: =ISNUMBER(PLOs!M14) | N13: =ISTEXT(PLOs!P14) | O13: =ISNUMBER(PLOs!Q14) | P13: =ISTEXT(PLOs!R14) | Q13: =ISNUMBER(PLOs!S14) | R13: =ISTEXT(PLOs!T14) | S13: =ISNUMBER(PLOs!U14) | T13: =ISTEXT(PLOs!V14) | U13: =ISNUMBER(PLOs!W14) | V13: =ISTEXT(PLOs!X14) | W13: =ISNUMBER(PLOs!Y14) | X13: =ISTEXT(PLOs!Z14) | Y13: =ISNUMBER(PLOs!AA14) | Z13: =ISTEXT(PLOs!AF14) | AA13: =ISNUMBER(PLOs!AG14) | AB13: =ISTEXT(PLOs!AH14) | AC13: =ISNUMBER(PLOs!AI14) | AD13: =ISTEXT(PLOs!AJ14) | AE13: =ISNUMBER(PLOs!AK14) | AF13: =ISTEXT(PLOs!AL14) | AG13: =ISNUMBER(PLOs!AM14) | AH13: =ISTEXT(PLOs!AN14) | AI13: =ISNUMBER(PLOs!AO14) | AJ13: =ISTEXT(PLOs!AP14) | AK13: =ISNUMBER(PLOs!AQ14) | AL13: =ISTEXT(PLOs!AR14) | AM13: =ISNUMBER(PLOs!AS14) | AN13: =ISTEXT(PLOs!AT14) | AO13: =ISNUMBER(PLOs!AU14)
F14: =ISTEXT(PLOs!F15) | G14: =ISNUMBER(PLOs!G15) | H14: =ISTEXT(PLOs!H15) | I14: =ISNUMBER(PLOs!I15) | J14: =ISTEXT(PLOs!J15) | K14: =ISNUMBER(PLOs!K15) | L14: =ISTEXT(PLOs!L15) | M14: =ISNUMBER(PLOs!M15) | N14: =ISTEXT(PLOs!P15) | O14: =ISNUMBER(PLOs!Q15) | P14: =ISTEXT(PLOs!R15) | Q14: =ISNUMBER(PLOs!S15) | R14: =ISTEXT(PLOs!T15) | S14: =ISNUMBER(PLOs!U15) | T14: =ISTEXT(PLOs!V15) | U14: =ISNUMBER(PLOs!W15) | V14: =ISTEXT(PLOs!X15) | W14: =ISNUMBER(PLOs!Y15) | X14: =ISTEXT(PLOs!Z15) | Y14: =ISNUMBER(PLOs!AA15) | Z14: =ISTEXT(PLOs!AF15) | AA14: =ISNUMBER(PLOs!AG15) | AB14: =ISTEXT(PLOs!AH15) | AC14: =ISNUMBER(PLOs!AI15) | AD14: =ISTEXT(PLOs!AJ15) | AE14: =ISNUMBER(PLOs!AK15) | AF14: =ISTEXT(PLOs!AL15) | AG14: =ISNUMBER(PLOs!AM15) | AH14: =ISTEXT(PLOs!AN15) | AI14: =ISNUMBER(PLOs!AO15) | AJ14: =ISTEXT(PLOs!AP15) | AK14: =ISNUMBER(PLOs!AQ15) | AL14: =ISTEXT(PLOs!AR15) | AM14: =ISNUMBER(PLOs!AS15) | AN14: =ISTEXT(PLOs!AT15) | AO14: =ISNUMBER(PLOs!AU15)
F15: =ISTEXT(PLOs!F16) | G15: =ISNUMBER(PLOs!G16) | H15: =ISTEXT(PLOs!H16) | I15: =ISNUMBER(PLOs!I16) | J15: =ISTEXT(PLOs!J16) | K15: =ISNUMBER(PLOs!K16) | L15: =ISTEXT(PLOs!L16) | M15: =ISNUMBER(PLOs!M16) | N15: =ISTEXT(PLOs!P16) | O15: =ISNUMBER(PLOs!Q16) | P15: =ISTEXT(PLOs!R16) | Q15: =ISNUMBER(PLOs!S16) | R15: =ISTEXT(PLOs!T16) | S15: =ISNUMBER(PLOs!U16) | T15: =ISTEXT(PLOs!V16) | U15: =ISNUMBER(PLOs!W16) | V15: =ISTEXT(PLOs!X16) | W15: =ISNUMBER(PLOs!Y16) | X15: =ISTEXT(PLOs!Z16) | Y15: =ISNUMBER(PLOs!AA16) | Z15: =ISTEXT(PLOs!AF16) | AA15: =ISNUMBER(PLOs!AG16) | AB15: =ISTEXT(PLOs!AH16) | AC15: =ISNUMBER(PLOs!AI16) | AD15: =ISTEXT(PLOs!AJ16) | AE15: =ISNUMBER(PLOs!AK16) | AF15: =ISTEXT(PLOs!AL16) | AG15: =ISNUMBER(PLOs!AM16) | AH15: =ISTEXT(PLOs!AN16) | AI15: =ISNUMBER(PLOs!AO16) | AJ15: =ISTEXT(PLOs!AP16) | AK15: =ISNUMBER(PLOs!AQ16) | AL15: =ISTEXT(PLOs!AR16) | AM15: =ISNUMBER(PLOs!AS16) | AN15: =ISTEXT(PLOs!AT16) | AO15: =ISNUMBER(PLOs!AU16)
F16: =ISTEXT(PLOs!F17) | G16: =ISNUMBER(PLOs!G17) | H16: =ISTEXT(PLOs!H17) | I16: =ISNUMBER(PLOs!I17) | J16: =ISTEXT(PLOs!J17) | K16: =ISNUMBER(PLOs!K17) | L16: =ISTEXT(PLOs!L17) | M16: =ISNUMBER(PLOs!M17) | N16: =ISTEXT(PLOs!P17) | O16: =ISNUMBER(PLOs!Q17) | P16: =ISTEXT(PLOs!R17) | Q16: =ISNUMBER(PLOs!S17) | R16: =ISTEXT(PLOs!T17) | S16: =ISNUMBER(PLOs!U17) | T16: =ISTEXT(PLOs!V17) | U16: =ISNUMBER(PLOs!W17) | V16: =ISTEXT(PLOs!X17) | W16: =ISNUMBER(PLOs!Y17) | X16: =ISTEXT(PLOs!Z17) | Y16: =ISNUMBER(PLOs!AA17) | Z16: =ISTEXT(PLOs!AF17) | AA16: =ISNUMBER(PLOs!AG17) | AB16: =ISTEXT(PLOs!AH17) | AC16: =ISNUMBER(PLOs!AI17) | AD16: =ISTEXT(PLOs!AJ17) | AE16: =ISNUMBER(PLOs!AK17) | AF16: =ISTEXT(PLOs!AL17) | AG16: =ISNUMBER(PLOs!AM17) | AH16: =ISTEXT(PLOs!AN17) | AI16: =ISNUMBER(PLOs!AO17) | AJ16: =ISTEXT(PLOs!AP17) | AK16: =ISNUMBER(PLOs!AQ17) | AL16: =ISTEXT(PLOs!AR17) | AM16: =ISNUMBER(PLOs!AS17) | AN16: =ISTEXT(PLOs!AT17) | AO16: =ISNUMBER(PLOs!AU17)
F17: =ISTEXT(PLOs!F18) | G17: =ISNUMBER(PLOs!G18) | H17: =ISTEXT(PLOs!H18) | I17: =ISNUMBER(PLOs!I18) | J17: =ISTEXT(PLOs!J18) | K17: =ISNUMBER(PLOs!K18) | L17: =ISTEXT(PLOs!L18) | M17: =ISNUMBER(PLOs!M18) | N17: =ISTEXT(PLOs!P18) | O17: =ISNUMBER(PLOs!Q18) | P17: =ISTEXT(PLOs!R18) | Q17: =ISNUMBER(PLOs!S18) | R17: =ISTEXT(PLOs!T18) | S17: =ISNUMBER(PLOs!U18) | T17: =ISTEXT(PLOs!V18) | U17: =ISNUMBER(PLOs!W18) | V17: =ISTEXT(PLOs!X18) | W17: =ISNUMBER(PLOs!Y18) | X17: =ISTEXT(PLOs!Z18) | Y17: =ISNUMBER(PLOs!AA18) | Z17: =ISTEXT(PLOs!AF18) | AA17: =ISNUMBER(PLOs!AG18) | AB17: =ISTEXT(PLOs!AH18) | AC17: =ISNUMBER(PLOs!AI18) | AD17: =ISTEXT(PLOs!AJ18) | AE17: =ISNUMBER(PLOs!AK18) | AF17: =ISTEXT(PLOs!AL18) | AG17: =ISNUMBER(PLOs!AM18) | AH17: =ISTEXT(PLOs!AN18) | AI17: =ISNUMBER(PLOs!AO18) | AJ17: =ISTEXT(PLOs!AP18) | AK17: =ISNUMBER(PLOs!AQ18) | AL17: =ISTEXT(PLOs!AR18) | AM17: =ISNUMBER(PLOs!AS18) | AN17: =ISTEXT(PLOs!AT18) | AO17: =ISNUMBER(PLOs!AU18)
F18: =ISTEXT(PLOs!F19) | G18: =ISNUMBER(PLOs!G19) | H18: =ISTEXT(PLOs!H19) | I18: =ISNUMBER(PLOs!I19) | J18: =ISTEXT(PLOs!J19) | K18: =ISNUMBER(PLOs!K19) | L18: =ISTEXT(PLOs!L19) | M18: =ISNUMBER(PLOs!M19) | N18: =ISTEXT(PLOs!P19) | O18: =ISNUMBER(PLOs!Q19) | P18: =ISTEXT(PLOs!R19) | Q18: =ISNUMBER(PLOs!S19) | R18: =ISTEXT(PLOs!T19) | S18: =ISNUMBER(PLOs!U19) | T18: =ISTEXT(PLOs!V19) | U18: =ISNUMBER(PLOs!W19) | V18: =ISTEXT(PLOs!X19) | W18: =ISNUMBER(PLOs!Y19) | X18: =ISTEXT(PLOs!Z19) | Y18: =ISNUMBER(PLOs!AA19) | Z18: =ISTEXT(PLOs!AF19) | AA18: =ISNUMBER(PLOs!AG19) | AB18: =ISTEXT(PLOs!AH19) | AC18: =ISNUMBER(PLOs!AI19) | AD18: =ISTEXT(PLOs!AJ19) | AE18: =ISNUMBER(PLOs!AK19) | AF18: =ISTEXT(PLOs!AL19) | AG18: =ISNUMBER(PLOs!AM19) | AH18: =ISTEXT(PLOs!AN19) | AI18: =ISNUMBER(PLOs!AO19) | AJ18: =ISTEXT(PLOs!AP19) | AK18: =ISNUMBER(PLOs!AQ19) | AL18: =ISTEXT(PLOs!AR19) | AM18: =ISNUMBER(PLOs!AS19) | AN18: =ISTEXT(PLOs!AT19) | AO18: =ISNUMBER(PLOs!AU19)
F19: =ISTEXT(PLOs!F20) | G19: =ISNUMBER(PLOs!G20) | H19: =ISTEXT(PLOs!H20) | I19: =ISNUMBER(PLOs!I20) | J19: =ISTEXT(PLOs!J20) | K19: =ISNUMBER(PLOs!K20) | L19: =ISTEXT(PLOs!L20) | M19: =ISNUMBER(PLOs!M20) | N19: =ISTEXT(PLOs!P20) | O19: =ISNUMBER(PLOs!Q20) | P19: =ISTEXT(PLOs!R20) | Q19: =ISNUMBER(PLOs!S20) | R19: =ISTEXT(PLOs!T20) | S19: =ISNUMBER(PLOs!U20) | T19: =ISTEXT(PLOs!V20) | U19: =ISNUMBER(PLOs!W20) | V19: =ISTEXT(PLOs!X20) | W19: =ISNUMBER(PLOs!Y20) | X19: =ISTEXT(PLOs!Z20) | Y19: =ISNUMBER(PLOs!AA20) | Z19: =ISTEXT(PLOs!AF20) | AA19: =ISNUMBER(PLOs!AG20) | AB19: =ISTEXT(PLOs!AH20) | AC19: =ISNUMBER(PLOs!AI20) | AD19: =ISTEXT(PLOs!AJ20) | AE19: =ISNUMBER(PLOs!AK20) | AF19: =ISTEXT(PLOs!AL20) | AG19: =ISNUMBER(PLOs!AM20) | AH19: =ISTEXT(PLOs!AN20) | AI19: =ISNUMBER(PLOs!AO20) | AJ19: =ISTEXT(PLOs!AP20) | AK19: =ISNUMBER(PLOs!AQ20) | AL19: =ISTEXT(PLOs!AR20) | AM19: =ISNUMBER(PLOs!AS20) | AN19: =ISTEXT(PLOs!AT20) | AO19: =ISNUMBER(PLOs!AU20)
F20: =ISTEXT(PLOs!F22) | G20: =ISNUMBER(PLOs!G22) | H20: =ISTEXT(PLOs!H22) | I20: =ISNUMBER(PLOs!I22) | J20: =ISTEXT(PLOs!J22) | K20: =ISNUMBER(PLOs!K22) | L20: =ISTEXT(PLOs!L22) | M20: =ISNUMBER(PLOs!M22) | N20: =ISTEXT(PLOs!P22) | O20: =ISNUMBER(PLOs!Q22) | P20: =ISTEXT(PLOs!R22) | Q20: =ISNUMBER(PLOs!S22) | R20: =ISTEXT(PLOs!T22) | S20: =ISNUMBER(PLOs!U22) | T20: =ISTEXT(PLOs!V22) | U20: =ISNUMBER(PLOs!W22) | V20: =ISTEXT(PLOs!X22) | W20: =ISNUMBER(PLOs!Y22) | X20: =ISTEXT(PLOs!Z22) | Y20: =ISNUMBER(PLOs!AA22) | Z20: =ISTEXT(PLOs!AF22) | AA20: =ISNUMBER(PLOs!AG22) | AB20: =ISTEXT(PLOs!AH22) | AC20: =ISNUMBER(PLOs!AI22) | AD20: =ISTEXT(PLOs!AJ22) | AE20: =ISNUMBER(PLOs!AK22) | AF20: =ISTEXT(PLOs!AL22) | AG20: =ISNUMBER(PLOs!AM22) | AH20: =ISTEXT(PLOs!AN22) | AI20: =ISNUMBER(PLOs!AO22) | AJ20: =ISTEXT(PLOs!AP22) | AK20: =ISNUMBER(PLOs!AQ22) | AL20: =ISTEXT(PLOs!AR22) | AM20: =ISNUMBER(PLOs!AS22) | AN20: =ISTEXT(PLOs!AT22) | AO20: =ISNUMBER(PLOs!AU22)
F21: =ISTEXT(PLOs!F23) | G21: =ISNUMBER(PLOs!G23) | H21: =ISTEXT(PLOs!H23) | I21: =ISNUMBER(PLOs!I23) | J21: =ISTEXT(PLOs!J23) | K21: =ISNUMBER(PLOs!K23) | L21: =ISTEXT(PLOs!L23) | M21: =ISNUMBER(PLOs!M23) | N21: =ISTEXT(PLOs!P23) | O21: =ISNUMBER(PLOs!Q23) | P21: =ISTEXT(PLOs!R23) | Q21: =ISNUMBER(PLOs!S23) | R21: =ISTEXT(PLOs!T23) | S21: =ISNUMBER(PLOs!U23) | T21: =ISTEXT(PLOs!V23) | U21: =ISNUMBER(PLOs!W23) | V21: =ISTEXT(PLOs!X23) | W21: =ISNUMBER(PLOs!Y23) | X21: =ISTEXT(PLOs!Z23) | Y21: =ISNUMBER(PLOs!AA23) | Z21: =ISTEXT(PLOs!AF23) | AA21: =ISNUMBER(PLOs!AG23) | AB21: =ISTEXT(PLOs!AH23) | AC21: =ISNUMBER(PLOs!AI23) | AD21: =ISTEXT(PLOs!AJ23) | AE21: =ISNUMBER(PLOs!AK23) | AF21: =ISTEXT(PLOs!AL23) | AG21: =ISNUMBER(PLOs!AM23) | AH21: =ISTEXT(PLOs!AN23) | AI21: =ISNUMBER(PLOs!AO23) | AJ21: =ISTEXT(PLOs!AP23) | AK21: =ISNUMBER(PLOs!AQ23) | AL21: =ISTEXT(PLOs!AR23) | AM21: =ISNUMBER(PLOs!AS23) | AN21: =ISTEXT(PLOs!AT23) | AO21: =ISNUMBER(PLOs!AU23)
F22: =ISTEXT(PLOs!F24) | G22: =ISNUMBER(PLOs!G24) | H22: =ISTEXT(PLOs!H24) | I22: =ISNUMBER(PLOs!I24) | J22: =ISTEXT(PLOs!J24) | K22: =ISNUMBER(PLOs!K24) | L22: =ISTEXT(PLOs!L24) | M22: =ISNUMBER(PLOs!M24) | N22: =ISTEXT(PLOs!P24) | O22: =ISNUMBER(PLOs!Q24) | P22: =ISTEXT(PLOs!R24) | Q22: =ISNUMBER(PLOs!S24) | R22: =ISTEXT(PLOs!T24) | S22: =ISNUMBER(PLOs!U24) | T22: =ISTEXT(PLOs!V24) | U22: =ISNUMBER(PLOs!W24) | V22: =ISTEXT(PLOs!X24) | W22: =ISNUMBER(PLOs!Y24) | X22: =ISTEXT(PLOs!Z24) | Y22: =ISNUMBER(PLOs!AA24) | Z22: =ISTEXT(PLOs!AF24) | AA22: =ISNUMBER(PLOs!AG24) | AB22: =ISTEXT(PLOs!AH24) | AC22: =ISNUMBER(PLOs!AI24) | AD22: =ISTEXT(PLOs!AJ24) | AE22: =ISNUMBER(PLOs!AK24) | AF22: =ISTEXT(PLOs!AL24) | AG22: =ISNUMBER(PLOs!AM24) | AH22: =ISTEXT(PLOs!AN24) | AI22: =ISNUMBER(PLOs!AO24) | AJ22: =ISTEXT(PLOs!AP24) | AK22: =ISNUMBER(PLOs!AQ24) | AL22: =ISTEXT(PLOs!AR24) | AM22: =ISNUMBER(PLOs!AS24) | AN22: =ISTEXT(PLOs!AT24) | AO22: =ISNUMBER(PLOs!AU24)
F23: =ISTEXT(PLOs!F25) | G23: =ISNUMBER(PLOs!G25) | H23: =ISTEXT(PLOs!H25) | I23: =ISNUMBER(PLOs!I25) | J23: =ISTEXT(PLOs!J25) | K23: =ISNUMBER(PLOs!K25) | L23: =ISTEXT(PLOs!L25) | M23: =ISNUMBER(PLOs!M25) | N23: =ISTEXT(PLOs!P25) | O23: =ISNUMBER(PLOs!Q25) | P23: =ISTEXT(PLOs!R25) | Q23: =ISNUMBER(PLOs!S25) | R23: =ISTEXT(PLOs!T25) | S23: =ISNUMBER(PLOs!U25) | T23: =ISTEXT(PLOs!V25) | U23: =ISNUMBER(PLOs!W25) | V23: =ISTEXT(PLOs!X25) | W23: =ISNUMBER(PLOs!Y25) | X23: =ISTEXT(PLOs!Z25) | Y23: =ISNUMBER(PLOs!AA25) | Z23: =ISTEXT(PLOs!AF25) | AA23: =ISNUMBER(PLOs!AG25) | AB23: =ISTEXT(PLOs!AH25) | AC23: =ISNUMBER(PLOs!AI25) | AD23: =ISTEXT(PLOs!AJ25) | AE23: =ISNUMBER(PLOs!AK25) | AF23: =ISTEXT(PLOs!AL25) | AG23: =ISNUMBER(PLOs!AM25) | AH23: =ISTEXT(PLOs!AN25) | AI23: =ISNUMBER(PLOs!AO25) | AJ23: =ISTEXT(PLOs!AP25) | AK23: =ISNUMBER(PLOs!AQ25) | AL23: =ISTEXT(PLOs!AR25) | AM23: =ISNUMBER(PLOs!AS25) | AN23: =ISTEXT(PLOs!AT25) | AO23: =ISNUMBER(PLOs!AU25)
F24: =ISTEXT(PLOs!F26) | G24: =ISNUMBER(PLOs!G26) | H24: =ISTEXT(PLOs!H26) | I24: =ISNUMBER(PLOs!I26) | J24: =ISTEXT(PLOs!J26) | K24: =ISNUMBER(PLOs!K26) | L24: =ISTEXT(PLOs!L26) | M24: =ISNUMBER(PLOs!M26) | N24: =ISTEXT(PLOs!P26) | O24: =ISNUMBER(PLOs!Q26) | P24: =ISTEXT(PLOs!R26) | Q24: =ISNUMBER(PLOs!S26) | R24: =ISTEXT(PLOs!T26) | S24: =ISNUMBER(PLOs!U26) | T24: =ISTEXT(PLOs!V26) | U24: =ISNUMBER(PLOs!W26) | V24: =ISTEXT(PLOs!X26) | W24: =ISNUMBER(PLOs!Y26) | X24: =ISTEXT(PLOs!Z26) | Y24: =ISNUMBER(PLOs!AA26) | Z24: =ISTEXT(PLOs!AF26) | AA24: =ISNUMBER(PLOs!AG26) | AB24: =ISTEXT(PLOs!AH26) | AC24: =ISNUMBER(PLOs!AI26) | AD24: =ISTEXT(PLOs!AJ26) | AE24: =ISNUMBER(PLOs!AK26) | AF24: =ISTEXT(PLOs!AL26) | AG24: =ISNUMBER(PLOs!AM26) | AH24: =ISTEXT(PLOs!AN26) | AI24: =ISNUMBER(PLOs!AO26) | AJ24: =ISTEXT(PLOs!AP26) | AK24: =ISNUMBER(PLOs!AQ26) | AL24: =ISTEXT(PLOs!AR26) | AM24: =ISNUMBER(PLOs!AS26) | AN24: =ISTEXT(PLOs!AT26) | AO24: =ISNUMBER(PLOs!AU26)
F25: =ISTEXT(PLOs!F27) | G25: =ISNUMBER(PLOs!G27) | H25: =ISTEXT(PLOs!H27) | I25: =ISNUMBER(PLOs!I27) | J25: =ISTEXT(PLOs!J27) | K25: =ISNUMBER(PLOs!K27) | L25: =ISTEXT(PLOs!L27) | M25: =ISNUMBER(PLOs!M27) | N25: =ISTEXT(PLOs!P27) | O25: =ISNUMBER(PLOs!Q27) | P25: =ISTEXT(PLOs!R27) | Q25: =ISNUMBER(PLOs!S27) | R25: =ISTEXT(PLOs!T27) | S25: =ISNUMBER(PLOs!U27) | T25: =ISTEXT(PLOs!V27) | U25: =ISNUMBER(PLOs!W27) | V25: =ISTEXT(PLOs!X27) | W25: =ISNUMBER(PLOs!Y27) | X25: =ISTEXT(PLOs!Z27) | Y25: =ISNUMBER(PLOs!AA27) | Z25: =ISTEXT(PLOs!AF27) | AA25: =ISNUMBER(PLOs!AG27) | AB25: =ISTEXT(PLOs!AH27) | AC25: =ISNUMBER(PLOs!AI27) | AD25: =ISTEXT(PLOs!AJ27) | AE25: =ISNUMBER(PLOs!AK27) | AF25: =ISTEXT(PLOs!AL27) | AG25: =ISNUMBER(PLOs!AM27) | AH25: =ISTEXT(PLOs!AN27) | AI25: =ISNUMBER(PLOs!AO27) | AJ25: =ISTEXT(PLOs!AP27) | AK25: =ISNUMBER(PLOs!AQ27) | AL25: =ISTEXT(PLOs!AR27) | AM25: =ISNUMBER(PLOs!AS27) | AN25: =ISTEXT(PLOs!AT27) | AO25: =ISNUMBER(PLOs!AU27)
F26: =ISTEXT(PLOs!#REF!) | G26: =ISNUMBER(PLOs!#REF!) | H26: =ISTEXT(PLOs!#REF!) | I26: =ISNUMBER(PLOs!#REF!) | J26: =ISTEXT(PLOs!#REF!) | K26: =ISNUMBER(PLOs!#REF!) | L26: =ISTEXT(PLOs!#REF!) | M26: =ISNUMBER(PLOs!#REF!) | N26: =ISTEXT(PLOs!#REF!) | O26: =ISNUMBER(PLOs!#REF!) | P26: =ISTEXT(PLOs!#REF!) | Q26: =ISNUMBER(PLOs!#REF!) | R26: =ISTEXT(PLOs!#REF!) | S26: =ISNUMBER(PLOs!#REF!) | T26: =ISTEXT(PLOs!#REF!) | U26: =ISNUMBER(PLOs!#REF!) | V26: =ISTEXT(PLOs!#REF!) | W26: =ISNUMBER(PLOs!#REF!) | X26: =ISTEXT(PLOs!#REF!) | Y26: =ISNUMBER(PLOs!#REF!) | Z26: =ISTEXT(PLOs!#REF!) | AA26: =ISNUMBER(PLOs!#REF!) | AB26: =ISTEXT(PLOs!#REF!) | AC26: =ISNUMBER(PLOs!#REF!) | AD26: =ISTEXT(PLOs!#REF!) | AE26: =ISNUMBER(PLOs!#REF!) | AF26: =ISTEXT(PLOs!#REF!) | AG26: =ISNUMBER(PLOs!#REF!) | AH26: =ISTEXT(PLOs!#REF!) | AI26: =ISNUMBER(PLOs!#REF!) | AJ26: =ISTEXT(PLOs!#REF!) | AK26: =ISNUMBER(PLOs!#REF!) | AL26: =ISTEXT(PLOs!#REF!) | AM26: =ISNUMBER(PLOs!#REF!) | AN26: =ISTEXT(PLOs!#REF!) | AO26: =ISNUMBER(PLOs!#REF!)
F27: =ISTEXT(PLOs!#REF!) | G27: =ISNUMBER(PLOs!#REF!) | H27: =ISTEXT(PLOs!#REF!) | I27: =ISNUMBER(PLOs!#REF!) | J27: =ISTEXT(PLOs!#REF!) | K27: =ISNUMBER(PLOs!#REF!) | L27: =ISTEXT(PLOs!#REF!) | M27: =ISNUMBER(PLOs!#REF!) | N27: =ISTEXT(PLOs!#REF!) | O27: =ISNUMBER(PLOs!#REF!) | P27: =ISTEXT(PLOs!#REF!) | Q27: =ISNUMBER(PLOs!#REF!) | R27: =ISTEXT(PLOs!#REF!) | S27: =ISNUMBER(PLOs!#REF!) | T27: =ISTEXT(PLOs!#REF!) | U27: =ISNUMBER(PLOs!#REF!) | V27: =ISTEXT(PLOs!#REF!) | W27: =ISNUMBER(PLOs!#REF!) | X27: =ISTEXT(PLOs!#REF!) | Y27: =ISNUMBER(PLOs!#REF!) | Z27: =ISTEXT(PLOs!#REF!) | AA27: =ISNUMBER(PLOs!#REF!) | AB27: =ISTEXT(PLOs!#REF!) | AC27: =ISNUMBER(PLOs!#REF!) | AD27: =ISTEXT(PLOs!#REF!) | AE27: =ISNUMBER(PLOs!#REF!) | AF27: =ISTEXT(PLOs!#REF!) | AG27: =ISNUMBER(PLOs!#REF!) | AH27: =ISTEXT(PLOs!#REF!) | AI27: =ISNUMBER(PLOs!#REF!) | AJ27: =ISTEXT(PLOs!#REF!) | AK27: =ISNUMBER(PLOs!#REF!) | AL27: =ISTEXT(PLOs!#REF!) | AM27: =ISNUMBER(PLOs!#REF!) | AN27: =ISTEXT(PLOs!#REF!) | AO27: =ISNUMBER(PLOs!#REF!)
F28: =ISTEXT(PLOs!#REF!) | G28: =ISNUMBER(PLOs!#REF!) | H28: =ISTEXT(PLOs!#REF!) | I28: =ISNUMBER(PLOs!#REF!) | J28: =ISTEXT(PLOs!#REF!) | K28: =ISNUMBER(PLOs!#REF!) | L28: =ISTEXT(PLOs!#REF!) | M28: =ISNUMBER(PLOs!#REF!) | N28: =ISTEXT(PLOs!#REF!) | O28: =ISNUMBER(PLOs!#REF!) | P28: =ISTEXT(PLOs!#REF!) | Q28: =ISNUMBER(PLOs!#REF!) | R28: =ISTEXT(PLOs!#REF!) | S28: =ISNUMBER(PLOs!#REF!) | T28: =ISTEXT(PLOs!#REF!) | U28: =ISNUMBER(PLOs!#REF!) | V28: =ISTEXT(PLOs!#REF!) | W28: =ISNUMBER(PLOs!#REF!) | X28: =ISTEXT(PLOs!#REF!) | Y28: =ISNUMBER(PLOs!#REF!) | Z28: =ISTEXT(PLOs!#REF!) | AA28: =ISNUMBER(PLOs!#REF!) | AB28: =ISTEXT(PLOs!#REF!) | AC28: =ISNUMBER(PLOs!#REF!) | AD28: =ISTEXT(PLOs!#REF!) | AE28: =ISNUMBER(PLOs!#REF!) | AF28: =ISTEXT(PLOs!#REF!) | AG28: =ISNUMBER(PLOs!#REF!) | AH28: =ISTEXT(PLOs!#REF!) | AI28: =ISNUMBER(PLOs!#REF!) | AJ28: =ISTEXT(PLOs!#REF!) | AK28: =ISNUMBER(PLOs!#REF!) | AL28: =ISTEXT(PLOs!#REF!) | AM28: =ISNUMBER(PLOs!#REF!) | AN28: =ISTEXT(PLOs!#REF!) | AO28: =ISNUMBER(PLOs!#REF!)
F29: =ISTEXT(PLOs!F28) | G29: =ISNUMBER(PLOs!G28) | H29: =ISTEXT(PLOs!H28) | I29: =ISNUMBER(PLOs!I28) | J29: =ISTEXT(PLOs!J28) | K29: =ISNUMBER(PLOs!K28) | L29: =ISTEXT(PLOs!L28) | M29: =ISNUMBER(PLOs!M28) | N29: =ISTEXT(PLOs!P28) | O29: =ISNUMBER(PLOs!Q28) | P29: =ISTEXT(PLOs!R28) | Q29: =ISNUMBER(PLOs!S28) | R29: =ISTEXT(PLOs!T28) | S29: =ISNUMBER(PLOs!U28) | T29: =ISTEXT(PLOs!V28) | U29: =ISNUMBER(PLOs!W28) | V29: =ISTEXT(PLOs!X28) | W29: =ISNUMBER(PLOs!Y28) | X29: =ISTEXT(PLOs!Z28) | Y29: =ISNUMBER(PLOs!AA28) | Z29: =ISTEXT(PLOs!AF28) | AA29: =ISNUMBER(PLOs!AG28) | AB29: =ISTEXT(PLOs!AH28) | AC29: =ISNUMBER(PLOs!AI28) | AD29: =ISTEXT(PLOs!AJ28) | AE29: =ISNUMBER(PLOs!AK28) | AF29: =ISTEXT(PLOs!AL28) | AG29: =ISNUMBER(PLOs!AM28) | AH29: =ISTEXT(PLOs!AN28) | AI29: =ISNUMBER(PLOs!AO28) | AJ29: =ISTEXT(PLOs!AP28) | AK29: =ISNUMBER(PLOs!AQ28) | AL29: =ISTEXT(PLOs!AR28) | AM29: =ISNUMBER(PLOs!AS28) | AN29: =ISTEXT(PLOs!AT28) | AO29: =ISNUMBER(PLOs!AU28)
F30: =ISTEXT(PLOs!G29) | G30: =ISNUMBER(PLOs!H29) | H30: =ISTEXT(PLOs!I29) | I30: =ISNUMBER(PLOs!J29) | J30: =ISTEXT(PLOs!K29) | K30: =ISNUMBER(PLOs!L29) | L30: =ISTEXT(PLOs!M29) | M30: =ISNUMBER(PLOs!N29) | N30: =ISTEXT(PLOs!Q29) | O30: =ISNUMBER(PLOs!R29) | P30: =ISTEXT(PLOs!S29) | Q30: =ISNUMBER(PLOs!T29) | R30: =ISTEXT(PLOs!U29) | S30: =ISNUMBER(PLOs!V29) | T30: =ISTEXT(PLOs!W29) | U30: =ISNUMBER(PLOs!X29) | V30: =ISTEXT(PLOs!Y29) | W30: =ISNUMBER(PLOs!Z29) | X30: =ISTEXT(PLOs!AA29) | Y30: =ISNUMBER(PLOs!AB29) | Z30: =ISTEXT(PLOs!AG29) | AA30: =ISNUMBER(PLOs!AH29) | AB30: =ISTEXT(PLOs!AI29) | AC30: =ISNUMBER(PLOs!AJ29) | AD30: =ISTEXT(PLOs!AK29) | AE30: =ISNUMBER(PLOs!AL29) | AF30: =ISTEXT(PLOs!AM29) | AG30: =ISNUMBER(PLOs!AN29) | AH30: =ISTEXT(PLOs!AO29) | AI30: =ISNUMBER(PLOs!AP29) | AJ30: =ISTEXT(PLOs!AQ29) | AK30: =ISNUMBER(PLOs!AR29) | AL30: =ISTEXT(PLOs!AS29) | AM30: =ISNUMBER(PLOs!AT29) | AN30: =ISTEXT(PLOs!AU29) | AO30: =ISNUMBER(PLOs!AV29)
F31: =ISTEXT(PLOs!G30) | G31: =ISNUMBER(PLOs!H30) | H31: =ISTEXT(PLOs!I30) | I31: =ISNUMBER(PLOs!J30) | J31: =ISTEXT(PLOs!K30) | K31: =ISNUMBER(PLOs!L30) | L31: =ISTEXT(PLOs!M30) | M31: =ISNUMBER(PLOs!N30) | N31: =ISTEXT(PLOs!Q30) | O31: =ISNUMBER(PLOs!R30) | P31: =ISTEXT(PLOs!S30) | Q31: =ISNUMBER(PLOs!T30) | R31: =ISTEXT(PLOs!U30) | S31: =ISNUMBER(PLOs!V30) | T31: =ISTEXT(PLOs!W30) | U31: =ISNUMBER(PLOs!X30) | V31: =ISTEXT(PLOs!Y30) | W31: =ISNUMBER(PLOs!Z30) | X31: =ISTEXT(PLOs!AA30) | Y31: =ISNUMBER(PLOs!AB30) | Z31: =ISTEXT(PLOs!AG30) | AA31: =ISNUMBER(PLOs!AH30) | AB31: =ISTEXT(PLOs!AI30) | AC31: =ISNUMBER(PLOs!AJ30) | AD31: =ISTEXT(PLOs!AK30) | AE31: =ISNUMBER(PLOs!AL30) | AF31: =ISTEXT(PLOs!AM30) | AG31: =ISNUMBER(PLOs!AN30) | AH31: =ISTEXT(PLOs!AO30) | AI31: =ISNUMBER(PLOs!AP30) | AJ31: =ISTEXT(PLOs!AQ30) | AK31: =ISNUMBER(PLOs!AR30) | AL31: =ISTEXT(PLOs!AS30) | AM31: =ISNUMBER(PLOs!AT30) | AN31: =ISTEXT(PLOs!AU30) | AO31: =ISNUMBER(PLOs!AV30)
F32: =ISTEXT(PLOs!#REF!) | G32: =ISNUMBER(PLOs!#REF!) | H32: =ISTEXT(PLOs!#REF!) | I32: =ISNUMBER(PLOs!#REF!) | J32: =ISTEXT(PLOs!#REF!) | K32: =ISNUMBER(PLOs!#REF!) | L32: =ISTEXT(PLOs!#REF!) | M32: =ISNUMBER(PLOs!#REF!) | N32: =ISTEXT(PLOs!#REF!) | O32: =ISNUMBER(PLOs!#REF!) | P32: =ISTEXT(PLOs!#REF!) | Q32: =ISNUMBER(PLOs!#REF!) | R32: =ISTEXT(PLOs!#REF!) | S32: =ISNUMBER(PLOs!#REF!) | T32: =ISTEXT(PLOs!#REF!) | U32: =ISNUMBER(PLOs!#REF!) | V32: =ISTEXT(PLOs!#REF!) | W32: =ISNUMBER(PLOs!#REF!) | X32: =ISTEXT(PLOs!#REF!) | Y32: =ISNUMBER(PLOs!#REF!) | Z32: =ISTEXT(PLOs!#REF!) | AA32: =ISNUMBER(PLOs!#REF!) | AB32: =ISTEXT(PLOs!#REF!) | AC32: =ISNUMBER(PLOs!#REF!) | AD32: =ISTEXT(PLOs!#REF!) | AE32: =ISNUMBER(PLOs!#REF!) | AF32: =ISTEXT(PLOs!#REF!) | AG32: =ISNUMBER(PLOs!#REF!) | AH32: =ISTEXT(PLOs!#REF!) | AI32: =ISNUMBER(PLOs!#REF!) | AJ32: =ISTEXT(PLOs!#REF!) | AK32: =ISNUMBER(PLOs!#REF!) | AL32: =ISTEXT(PLOs!#REF!) | AM32: =ISNUMBER(PLOs!#REF!) | AN32: =ISTEXT(PLOs!#REF!) | AO32: =ISNUMBER(PLOs!#REF!)
F33: =ISTEXT(PLOs!#REF!) | G33: =ISNUMBER(PLOs!#REF!) | H33: =ISTEXT(PLOs!#REF!) | I33: =ISNUMBER(PLOs!#REF!) | J33: =ISTEXT(PLOs!#REF!) | K33: =ISNUMBER(PLOs!#REF!) | L33: =ISTEXT(PLOs!#REF!) | M33: =ISNUMBER(PLOs!#REF!) | N33: =ISTEXT(PLOs!#REF!) | O33: =ISNUMBER(PLOs!#REF!) | P33: =ISTEXT(PLOs!#REF!) | Q33: =ISNUMBER(PLOs!#REF!) | R33: =ISTEXT(PLOs!#REF!) | S33: =ISNUMBER(PLOs!#REF!) | T33: =ISTEXT(PLOs!#REF!) | U33: =ISNUMBER(PLOs!#REF!) | V33: =ISTEXT(PLOs!#REF!) | W33: =ISNUMBER(PLOs!#REF!) | X33: =ISTEXT(PLOs!#REF!) | Y33: =ISNUMBER(PLOs!#REF!) | Z33: =ISTEXT(PLOs!#REF!) | AA33: =ISNUMBER(PLOs!#REF!) | AB33: =ISTEXT(PLOs!#REF!) | AC33: =ISNUMBER(PLOs!#REF!) | AD33: =ISTEXT(PLOs!#REF!) | AE33: =ISNUMBER(PLOs!#REF!) | AF33: =ISTEXT(PLOs!#REF!) | AG33: =ISNUMBER(PLOs!#REF!) | AH33: =ISTEXT(PLOs!#REF!) | AI33: =ISNUMBER(PLOs!#REF!) | AJ33: =ISTEXT(PLOs!#REF!) | AK33: =ISNUMBER(PLOs!#REF!) | AL33: =ISTEXT(PLOs!#REF!) | AM33: =ISNUMBER(PLOs!#REF!) | AN33: =ISTEXT(PLOs!#REF!) | AO33: =ISNUMBER(PLOs!#REF!)
F34: =ISTEXT(PLOs!#REF!) | G34: =ISNUMBER(PLOs!#REF!) | H34: =ISTEXT(PLOs!#REF!) | I34: =ISNUMBER(PLOs!#REF!) | J34: =ISTEXT(PLOs!#REF!) | K34: =ISNUMBER(PLOs!#REF!) | L34: =ISTEXT(PLOs!#REF!) | M34: =ISNUMBER(PLOs!#REF!) | N34: =ISTEXT(PLOs!#REF!) | O34: =ISNUMBER(PLOs!#REF!) | P34: =ISTEXT(PLOs!#REF!) | Q34: =ISNUMBER(PLOs!#REF!) | R34: =ISTEXT(PLOs!#REF!) | S34: =ISNUMBER(PLOs!#REF!) | T34: =ISTEXT(PLOs!#REF!) | U34: =ISNUMBER(PLOs!#REF!) | V34: =ISTEXT(PLOs!#REF!) | W34: =ISNUMBER(PLOs!#REF!) | X34: =ISTEXT(PLOs!#REF!) | Y34: =ISNUMBER(PLOs!#REF!) | Z34: =ISTEXT(PLOs!#REF!) | AA34: =ISNUMBER(PLOs!#REF!) | AB34: =ISTEXT(PLOs!#REF!) | AC34: =ISNUMBER(PLOs!#REF!) | AD34: =ISTEXT(PLOs!#REF!) | AE34: =ISNUMBER(PLOs!#REF!) | AF34: =ISTEXT(PLOs!#REF!) | AG34: =ISNUMBER(PLOs!#REF!) | AH34: =ISTEXT(PLOs!#REF!) | AI34: =ISNUMBER(PLOs!#REF!) | AJ34: =ISTEXT(PLOs!#REF!) | AK34: =ISNUMBER(PLOs!#REF!) | AL34: =ISTEXT(PLOs!#REF!) | AM34: =ISNUMBER(PLOs!#REF!) | AN34: =ISTEXT(PLOs!#REF!) | AO34: =ISNUMBER(PLOs!#REF!)
F35: =ISTEXT(PLOs!#REF!) | G35: =ISNUMBER(PLOs!#REF!) | H35: =ISTEXT(PLOs!#REF!) | I35: =ISNUMBER(PLOs!#REF!) | J35: =ISTEXT(PLOs!#REF!) | K35: =ISNUMBER(PLOs!#REF!) | L35: =ISTEXT(PLOs!#REF!) | M35: =ISNUMBER(PLOs!#REF!) | N35: =ISTEXT(PLOs!#REF!) | O35: =ISNUMBER(PLOs!#REF!) | P35: =ISTEXT(PLOs!#REF!) | Q35: =ISNUMBER(PLOs!#REF!) | R35: =ISTEXT(PLOs!#REF!) | S35: =ISNUMBER(PLOs!#REF!) | T35: =ISTEXT(PLOs!#REF!) | U35: =ISNUMBER(PLOs!#REF!) | V35: =ISTEXT(PLOs!#REF!) | W35: =ISNUMBER(PLOs!#REF!) | X35: =ISTEXT(PLOs!#REF!) | Y35: =ISNUMBER(PLOs!#REF!) | Z35: =ISTEXT(PLOs!#REF!) | AA35: =ISNUMBER(PLOs!#REF!) | AB35: =ISTEXT(PLOs!#REF!) | AC35: =ISNUMBER(PLOs!#REF!) | AD35: =ISTEXT(PLOs!#REF!) | AE35: =ISNUMBER(PLOs!#REF!) | AF35: =ISTEXT(PLOs!#REF!) | AG35: =ISNUMBER(PLOs!#REF!) | AH35: =ISTEXT(PLOs!#REF!) | AI35: =ISNUMBER(PLOs!#REF!) | AJ35: =ISTEXT(PLOs!#REF!) | AK35: =ISNUMBER(PLOs!#REF!) | AL35: =ISTEXT(PLOs!#REF!) | AM35: =ISNUMBER(PLOs!#REF!) | AN35: =ISTEXT(PLOs!#REF!) | AO35: =ISNUMBER(PLOs!#REF!)
F36: =ISTEXT(PLOs!#REF!) | G36: =ISNUMBER(PLOs!#REF!) | H36: =ISTEXT(PLOs!#REF!) | I36: =ISNUMBER(PLOs!#REF!) | J36: =ISTEXT(PLOs!#REF!) | K36: =ISNUMBER(PLOs!#REF!) | L36: =ISTEXT(PLOs!#REF!) | M36: =ISNUMBER(PLOs!#REF!) | N36: =ISTEXT(PLOs!#REF!) | O36: =ISNUMBER(PLOs!#REF!) | P36: =ISTEXT(PLOs!#REF!) | Q36: =ISNUMBER(PLOs!#REF!) | R36: =ISTEXT(PLOs!#REF!) | S36: =ISNUMBER(PLOs!#REF!) | T36: =ISTEXT(PLOs!#REF!) | U36: =ISNUMBER(PLOs!#REF!) | V36: =ISTEXT(PLOs!#REF!) | W36: =ISNUMBER(PLOs!#REF!) | X36: =ISTEXT(PLOs!#REF!) | Y36: =ISNUMBER(PLOs!#REF!) | Z36: =ISTEXT(PLOs!#REF!) | AA36: =ISNUMBER(PLOs!#REF!) | AB36: =ISTEXT(PLOs!#REF!) | AC36: =ISNUMBER(PLOs!#REF!) | AD36: =ISTEXT(PLOs!#REF!) | AE36: =ISNUMBER(PLOs!#REF!) | AF36: =ISTEXT(PLOs!#REF!) | AG36: =ISNUMBER(PLOs!#REF!) | AH36: =ISTEXT(PLOs!#REF!) | AI36: =ISNUMBER(PLOs!#REF!) | AJ36: =ISTEXT(PLOs!#REF!) | AK36: =ISNUMBER(PLOs!#REF!) | AL36: =ISTEXT(PLOs!#REF!) | AM36: =ISNUMBER(PLOs!#REF!) | AN36: =ISTEXT(PLOs!#REF!) | AO36: =ISNUMBER(PLOs!#REF!)
F37: =ISTEXT(PLOs!#REF!) | G37: =ISNUMBER(PLOs!#REF!) | H37: =ISTEXT(PLOs!#REF!) | I37: =ISNUMBER(PLOs!#REF!) | J37: =ISTEXT(PLOs!#REF!) | K37: =ISNUMBER(PLOs!#REF!) | L37: =ISTEXT(PLOs!#REF!) | M37: =ISNUMBER(PLOs!#REF!) | N37: =ISTEXT(PLOs!#REF!) | O37: =ISNUMBER(PLOs!#REF!) | P37: =ISTEXT(PLOs!#REF!) | Q37: =ISNUMBER(PLOs!#REF!) | R37: =ISTEXT(PLOs!#REF!) | S37: =ISNUMBER(PLOs!#REF!) | T37: =ISTEXT(PLOs!#REF!) | U37: =ISNUMBER(PLOs!#REF!) | V37: =ISTEXT(PLOs!#REF!) | W37: =ISNUMBER(PLOs!#REF!) | X37: =ISTEXT(PLOs!#REF!) | Y37: =ISNUMBER(PLOs!#REF!) | Z37: =ISTEXT(PLOs!#REF!) | AA37: =ISNUMBER(PLOs!#REF!) | AB37: =ISTEXT(PLOs!#REF!) | AC37: =ISNUMBER(PLOs!#REF!) | AD37: =ISTEXT(PLOs!#REF!) | AE37: =ISNUMBER(PLOs!#REF!) | AF37: =ISTEXT(PLOs!#REF!) | AG37: =ISNUMBER(PLOs!#REF!) | AH37: =ISTEXT(PLOs!#REF!) | AI37: =ISNUMBER(PLOs!#REF!) | AJ37: =ISTEXT(PLOs!#REF!) | AK37: =ISNUMBER(PLOs!#REF!) | AL37: =ISTEXT(PLOs!#REF!) | AM37: =ISNUMBER(PLOs!#REF!) | AN37: =ISTEXT(PLOs!#REF!) | AO37: =ISNUMBER(PLOs!#REF!)
F38: =ISTEXT(PLOs!G31) | G38: =ISNUMBER(PLOs!H31) | H38: =ISTEXT(PLOs!I31) | I38: =ISNUMBER(PLOs!J31) | J38: =ISTEXT(PLOs!K31) | K38: =ISNUMBER(PLOs!L31) | L38: =ISTEXT(PLOs!M31) | M38: =ISNUMBER(PLOs!N31) | N38: =ISTEXT(PLOs!Q31) | O38: =ISNUMBER(PLOs!R31) | P38: =ISTEXT(PLOs!S31) | Q38: =ISNUMBER(PLOs!T31) | R38: =ISTEXT(PLOs!U31) | S38: =ISNUMBER(PLOs!V31) | T38: =ISTEXT(PLOs!W31) | U38: =ISNUMBER(PLOs!X31) | V38: =ISTEXT(PLOs!Y31) | W38: =ISNUMBER(PLOs!AA31) | X38: =ISTEXT(PLOs!AB31) | Y38: =ISNUMBER(PLOs!#REF!) | Z38: =ISTEXT(PLOs!AG31) | AA38: =ISNUMBER(PLOs!AH31) | AB38: =ISTEXT(PLOs!AI31) | AC38: =ISNUMBER(PLOs!AJ31) | AD38: =ISTEXT(PLOs!AK31) | AE38: =ISNUMBER(PLOs!AL31) | AF38: =ISTEXT(PLOs!AM31) | AG38: =ISNUMBER(PLOs!AN31) | AH38: =ISTEXT(PLOs!AO31) | AI38: =ISNUMBER(PLOs!AP31) | AJ38: =ISTEXT(PLOs!AQ31) | AK38: =ISNUMBER(PLOs!AR31) | AL38: =ISTEXT(PLOs!AS31) | AM38: =ISNUMBER(PLOs!AT31) | AN38: =ISTEXT(PLOs!AU31) | AO38: =ISNUMBER(PLOs!AV31)
F39: =ISTEXT(PLOs!G32) | G39: =ISNUMBER(PLOs!H32) | H39: =ISTEXT(PLOs!I32) | I39: =ISNUMBER(PLOs!J32) | J39: =ISTEXT(PLOs!K32) | K39: =ISNUMBER(PLOs!L32) | L39: =ISTEXT(PLOs!M32) | M39: =ISNUMBER(PLOs!N32) | N39: =ISTEXT(PLOs!Q32) | O39: =ISNUMBER(PLOs!R32) | P39: =ISTEXT(PLOs!S32) | Q39: =ISNUMBER(PLOs!T32) | R39: =ISTEXT(PLOs!U32) | S39: =ISNUMBER(PLOs!V32) | T39: =ISTEXT(PLOs!W32) | U39: =ISNUMBER(PLOs!X32) | V39: =ISTEXT(PLOs!Y32) | W39: =ISNUMBER(PLOs!Z32) | X39: =ISTEXT(PLOs!AA32) | Y39: =ISNUMBER(PLOs!AB32) | Z39: =ISTEXT(PLOs!AG32) | AA39: =ISNUMBER(PLOs!AH32) | AB39: =ISTEXT(PLOs!AI32) | AC39: =ISNUMBER(PLOs!AJ32) | AD39: =ISTEXT(PLOs!AK32) | AE39: =ISNUMBER(PLOs!AL32) | AF39: =ISTEXT(PLOs!AM32) | AG39: =ISNUMBER(PLOs!AN32) | AH39: =ISTEXT(PLOs!AO32) | AI39: =ISNUMBER(PLOs!AP32) | AJ39: =ISTEXT(PLOs!AQ32) | AK39: =ISNUMBER(PLOs!AR32) | AL39: =ISTEXT(PLOs!AS32) | AM39: =ISNUMBER(PLOs!AT32) | AN39: =ISTEXT(PLOs!AU32) | AO39: =ISNUMBER(PLOs!AV32)
F40: =ISTEXT(PLOs!G33) | G40: =ISNUMBER(PLOs!H33) | H40: =ISTEXT(PLOs!I33) | I40: =ISNUMBER(PLOs!J33) | J40: =ISTEXT(PLOs!K33) | K40: =ISNUMBER(PLOs!L33) | L40: =ISTEXT(PLOs!M33) | M40: =ISNUMBER(PLOs!N33) | N40: =ISTEXT(PLOs!Q33) | O40: =ISNUMBER(PLOs!R33) | P40: =ISTEXT(PLOs!S33) | Q40: =ISNUMBER(PLOs!T33) | R40: =ISTEXT(PLOs!U33) | S40: =ISNUMBER(PLOs!V33) | T40: =ISTEXT(PLOs!W33) | U40: =ISNUMBER(PLOs!X33) | V40: =ISTEXT(PLOs!Y33) | W40: =ISNUMBER(PLOs!Z33) | X40: =ISTEXT(PLOs!AA33) | Y40: =ISNUMBER(PLOs!AB33) | Z40: =ISTEXT(PLOs!AG33) | AA40: =ISNUMBER(PLOs!AH33) | AB40: =ISTEXT(PLOs!AI33) | AC40: =ISNUMBER(PLOs!#REF!) | AD40: =ISTEXT(PLOs!AJ33) | AE40: =ISNUMBER(PLOs!AK33) | AF40: =ISTEXT(PLOs!AL33) | AG40: =ISNUMBER(PLOs!AM33) | AH40: =ISTEXT(PLOs!AN33) | AI40: =ISNUMBER(PLOs!AO33) | AJ40: =ISTEXT(PLOs!AP33) | AK40: =ISNUMBER(PLOs!AQ33) | AL40: =ISTEXT(PLOs!AR33) | AM40: =ISNUMBER(PLOs!AS33) | AN40: =ISTEXT(PLOs!AU33) | AO40: =ISNUMBER(PLOs!AV33)
...
